Workbook

Sheet Juin 2026
A1: N° | C1: Nom Client | D1: Nom | E1: Activité | F1: Tx Jour | G1: Taux Horaire | H1: Heure contrat (7 si 35h 7,5 si 37,5) | I1: Total Heures | J1: Equiv Jours | K1: HS à refacturer sur l'AS | L1: Montant 125% | M1: Méca | N1: Calcul | O1: Elec | P1: L | Q1: M | R1: M | S1: J | T1: V | U1: S | V1: D | W1: L | X1: M | Y1: M | Z1: J | AA1: V | AB1: S | AC1: D | AD1: L | AE1: M | AF1: M | AG1: J | AH1: V | AI1: S | AJ1: D | AK1: L | AL1: M | AM1: M | AN1: J | AO1: V | AP1: S | AQ1: D | AR1: L | AS1: M | AV1: Jours/heures en commande initiale | AW1: Jours/heures restant sur la commande
P2: 1 | Q2: 2 | R2: 3 | S2: 4 | T2: 5 | U2: 6 | V2: 7 | W2: 8 | X2: 9 | Y2: 10 | Z2: 11 | AA2: 12 | AB2: 13 | AC2: 14 | AD2: 15 | AE2: 16 | AF2: 17 | AG2: 18 | AH2: 19 | AI2: 20 | AJ2: 21 | AK2: 22 | AL2: 23 | AM2: 24 | AN2: 25 | AO2: 26 | AP2: 27 | AQ2: 28 | AR2: 29 | AS2: 30
P3: 23 | W3: 24 | AD3: 25 | AK3: 26 | AR3: 27
A4: PRESTATION EXTERNE en TARIF JOURNALIER
A5: CBE | E5: =IFERROR(VLOOKUP(D5,[1]Données!A:B,2,FALSE),"") | G5: =IFERROR(F5/H5,"") | I5: =SUM(P5:AT5) -> 0 | J5: =IFERROR(I5/H5,"") | L5: =IFERROR((K5*1.25)*G5,"") | M5: =IF($E5="Méca",I5*G5+L5,"") | N5: =IF($E5="Calcul",I5*G5+L5,"") | O5: =IF($E5="Elec",I5*G5+L5,"") | AW5: =AV5-J5 -> #VALUE!
A6: CBE | E6: =IFERROR(VLOOKUP(D6,[1]Données!A:B,2,FALSE),"") | G6: =IFERROR(F6/H6,"") | I6: =SUM(P6:AT6) -> 0 | J6: =IFERROR(I6/H6,"") | L6: =IFERROR((K6*1.25)*G6,"") | M6: =IF($E6="Méca",I6*G6+L6,"") | N6: =IF($E6="Calcul",I6*G6+L6,"") | O6: =IF($E6="Elec",I6*G6+L6,"") | AW6: =AV6-J6 -> #VALUE!
A7: CBE | E7: =IFERROR(VLOOKUP(D7,[1]Données!A:B,2,FALSE),"") | G7: =IFERROR(F7/H7,"") | I7: =SUM(P7:AT7) -> 0 | J7: =IFERROR(I7/H7,"") | L7: =IFERROR((K7*1.25)*G7,"") | M7: =IF($E7="Méca",I7*G7+L7,"") | N7: =IF($E7="Calcul",I7*G7+L7,"") | O7: =IF($E7="Elec",I7*G7+L7,"") | AW7: =AV7-J7 -> #VALUE!
A8: CBE | E8: =IFERROR(VLOOKUP(D8,[1]Données!A:B,2,FALSE),"") | G8: =IFERROR(F8/H8,"") | I8: =SUM(P8:AT8) -> 0 | J8: =IFERROR(I8/H8,"") | L8: =IFERROR((K8*1.25)*G8,"") | M8: =IF($E8="Méca",I8*G8+L8,"") | N8: =IF($E8="Calcul",I8*G8+L8,"") | O8: =IF($E8="Elec",I8*G8+L8,"") | AW8: =AV8-J8 -> #VALUE!
A9: CBE | E9: =IFERROR(VLOOKUP(D9,[1]Données!A:B,2,FALSE),"") | G9: =IFERROR(F9/H9,"") | I9: =SUM(P9:AT9) -> 0 | J9: =IFERROR(I9/H9,"") | L9: =IFERROR((K9*1.25)*G9,"") | M9: =IF($E9="Méca",I9*G9+L9,"") | N9: =IF($E9="Calcul",I9*G9+L9,"") | O9: =IF($E9="Elec",I9*G9+L9,"") | AW9: =AV9-J9 -> #VALUE!
A10: CBE | E10: =IFERROR(VLOOKUP(D10,[1]Données!A:B,2,FALSE),"") | G10: =IFERROR(F10/H10,"") | I10: =SUM(P10:AT10) -> 0 | J10: =IFERROR(I10/H10,"") | L10: =IFERROR((K10*1.25)*G10,"") | M10: =IF($E10="Méca",I10*G10+L10,"") | N10: =IF($E10="Calcul",I10*G10+L10,"") | O10: =IF($E10="Elec",I10*G10+L10,"") | AW10: =AV10-J10 -> #VALUE!
A11: CBE | E11: =IFERROR(VLOOKUP(D11,[1]Données!A:B,2,FALSE),"") | G11: =IFERROR(F11/H11,"") | I11: =SUM(P11:AT11) -> 0 | J11: =IFERROR(I11/H11,"") | L11: =IFERROR((K11*1.25)*G11,"") | M11: =IF($E11="Méca",I11*G11+L11,"") | N11: =IF($E11="Calcul",I11*G11+L11,"") | O11: =IF($E11="Elec",I11*G11+L11,"") | AW11: =AV11-J11 -> #VALUE!
A12: CBE | E12: =IFERROR(VLOOKUP(D12,[1]Données!A:B,2,FALSE),"") | G12: =IFERROR(F12/H12,"") | I12: =SUM(P12:AT12) -> 0 | J12: =IFERROR(I12/H12,"") | L12: =IFERROR((K12*1.25)*G12,"") | M12: =IF($E12="Méca",I12*G12+L12,"") | N12: =IF($E12="Calcul",I12*G12+L12,"") | O12: =IF($E12="Elec",I12*G12+L12,"") | AW12: =AV12-J12 -> #VALUE!
A13: CBE | E13: =IFERROR(VLOOKUP(D13,[1]Données!A:B,2,FALSE),"") | G13: =IFERROR(F13/H13,"") | I13: =SUM(P13:AT13) -> 0 | J13: =IFERROR(I13/H13,"") | L13: =IFERROR((K13*1.25)*G13,"") | M13: =IF($E13="Méca",I13*G13+L13,"") | N13: =IF($E13="Calcul",I13*G13+L13,"") | O13: =IF($E13="Elec",I13*G13+L13,"") | AW13: =AV13-J13 -> #VALUE!
A14: CBE | E14: =IFERROR(VLOOKUP(D14,[1]Données!A:B,2,FALSE),"") | I14: 0 | J14: =IFERROR(I14/H14,"") | L14: =IFERROR((K14*1.25)*G14,"") -> 0 | M14: =IF($E14="Méca",I14*G14+L14,"") | N14: =IF($E14="Calcul",I14*G14+L14,"") | O14: =IF($E14="Elec",I14*G14+L14,"") | AW14: =AV14-J14 -> #VALUE!
A15: CBE | E15: =IFERROR(VLOOKUP(D15,[1]Données!A:B,2,FALSE),"") | G15: =IFERROR(F15/H15,"") | I15: =SUM(P15:AT15) -> 0 | J15: =IFERROR(I15/H15,"") | L15: =IFERROR((K15*1.25)*G15,"") | M15: =IF($E15="Méca",I15*G15+L15,"") | N15: =IF($E15="Calcul",I15*G15+L15,"") | O15: =IF($E15="Elec",I15*G15+L15,"") | AW15: =AV15-J15 -> #VALUE!
A16: CBE | E16: =IFERROR(VLOOKUP(D16,[1]Données!A:B,2,FALSE),"") | G16: =IFERROR(F16/H16,"") | I16: =SUM(P16:AT16) -> 0 | J16: =IFERROR(I16/H16,"") | L16: =IFERROR((K16*1.25)*G16,"") | M16: =IF($E16="Méca",I16*G16+L16,"") | N16: =IF($E16="Calcul",I16*G16+L16,"") | O16: =IF($E16="Elec",I16*G16+L16,"") | AW16: =AV16-J16 -> #VALUE!
A17: CBE | E17: =IFERROR(VLOOKUP(D17,[1]Données!A:B,2,FALSE),"") | G17: =IFERROR(F17/H17,"") | I17: =SUM(P17:AT17) -> 0 | J17: =IFERROR(I17/H17,"") | L17: =IFERROR((K17*1.25)*G17,"") | M17: =IF($E17="Méca",I17*G17+L17,"") | N17: =IF($E17="Calcul",I17*G17+L17,"") | O17: =IF($E17="Elec",I17*G17+L17,"") | AW17: =AV17-J17 -> #VALUE!
A18: CBE | E18: =IFERROR(VLOOKUP(D18,[1]Données!A:B,2,FALSE),"") | G18: =IFERROR(F18/H18,"") | I18: =SUM(P18:AT18) -> 0 | J18: =IFERROR(I18/H18,"") | L18: =IFERROR((K18*1.25)*G18,"") | M18: =IF($E18="Méca",I18*G18+L18,"") | N18: =IF($E18="Calcul",I18*G18+L18,"") | O18: =IF($E18="Elec",I18*G18+L18,"") | AW18: =AV18-J18 -> #VALUE!
A19: CBE | E19: =IFERROR(VLOOKUP(D19,[1]Données!A:B,2,FALSE),"") | G19: =IFERROR(F19/H19,"") | I19: =SUM(P19:AT19) -> 0 | J19: =IFERROR(I19/H19,"") | L19: =IFERROR((K19*1.25)*G19,"") | M19: =IF($E19="Méca",I19*G19+L19,"") | N19: =IF($E19="Calcul",I19*G19+L19,"") | O19: =IF($E19="Elec",I19*G19+L19,"") | AW19: =AV19-J19 -> #VALUE!
A20: CBE | E20: =IFERROR(VLOOKUP(D20,[1]Données!A:B,2,FALSE),"") | G20: =IFERROR(F20/H20,"") | I20: =SUM(P20:AT20) -> 0 | J20: =IFERROR(I20/H20,"") | L20: =IFERROR((K20*1.25)*G20,"") | M20: =IF($E20="Méca",I20*G20+L20,"") | N20: =IF($E20="Calcul",I20*G20+L20,"") | O20: =IF($E20="Elec",I20*G20+L20,"") | AW20: =AV20-J20 -> #VALUE!
A21: CBE | E21: =IFERROR(VLOOKUP(D21,[1]Données!A:B,2,FALSE),"") | G21: =IFERROR(F21/H21,"") | I21: =SUM(P21:AT21) -> 0 | J21: =IFERROR(I21/H21,"") | L21: =IFERROR((K21*1.25)*G21,"") | M21: =IF($E21="Méca",I21*G21+L21,"") | N21: =IF($E21="Calcul",I21*G21+L21,"") | O21: =IF($E21="Elec",I21*G21+L21,"") | AW21: =AV21-J21 -> #VALUE!
A22: PRESTATION EXTERNE en TARIF HORAIRE
A23: CBE | E23: =IFERROR(VLOOKUP(D23,[1]Données!A:B,2,FALSE),"") | F23: =G23*H23 -> 0 | I23: =SUM(P23:AT23) -> 0 | J23: =IFERROR(I23/H23,"") | L23: =IFERROR((K23*1.25)*G23,"") -> 0 | M23: =IF($E23="Méca",I23*G23+L23,"") | N23: =IF($E23="Calcul",I23*G23+L23,"") | O23: =IF($E23="Elec",I23*G23+L23,"") | AW23: =AV23-I23 -> 0
A24: CBE | E24: =IFERROR(VLOOKUP(D24,[1]Données!A:B,2,FALSE),"") | F24: =G24*H24 -> 0 | I24: =SUM(P24:AT24) -> 0 | J24: =IFERROR(I24/H24,"") | L24: =IFERROR((K24*1.25)*G24,"") -> 0 | M24: =IF($E24="Méca",I24*G24+L24,"") | N24: =IF($E24="Calcul",I24*G24+L24,"") | O24: =IF($E24="Elec",I24*G24+L24,"") | AW24: =AV24-I24 -> 0
A25: CBE | E25: =IFERROR(VLOOKUP(D25,[1]Données!A:B,2,FALSE),"") | F25: =G25*H25 -> 0 | I25: =SUM(P25:AT25) -> 0 | J25: =IFERROR(I25/H25,"") | L25: =IFERROR((K25*1.25)*G25,"") -> 0 | M25: =IF($E25="Méca",I25*G25+L25,"") | N25: =IF($E25="Calcul",I25*G25+L25,"") | O25: =IF($E25="Elec",I25*G25+L25,"") | AW25: =AV25-I25 -> 0
A26: CBE | E26: =IFERROR(VLOOKUP(D26,[1]Données!A:B,2,FALSE),"") | F26: =G26*H26 -> 0 | I26: =SUM(P26:AT26) -> 0 | J26: =IFERROR(I26/H26,"") | L26: =IFERROR((K26*1.25)*G26,"") -> 0 | M26: =IF($E26="Méca",I26*G26+L26,"") | N26: =IF($E26="Calcul",I26*G26+L26,"") | O26: =IF($E26="Elec",I26*G26+L26,"") | AW26: =AV26-I26 -> 0
A27: CBE | E27: =IFERROR(VLOOKUP(D27,[1]Données!A:B,2,FALSE),"") | F27: =G27*H27 -> 0 | I27: =SUM(P27:AT27) -> 0 | J27: =IFERROR(I27/H27,"") | L27: =IFERROR((K27*1.25)*G27,"") -> 0 | M27: =IF($E27="Méca",I27*G27+L27,"") | N27: =IF($E27="Calcul",I27*G27+L27,"") | O27: =IF($E27="Elec",I27*G27+L27,"") | AW27: =AV27-I27 -> 0
A28: CBE | E28: =IFERROR(VLOOKUP(D28,[1]Données!A:B,2,FALSE),"") | F28: =G28*H28 -> 0 | I28: =SUM(P28:AT28) -> 0 | J28: =IFERROR(I28/H28,"") | L28: =IFERROR((K28*1.25)*G28,"") -> 0 | M28: =IF($E28="Méca",I28*G28+L28,"") | N28: =IF($E28="Calcul",I28*G28+L28,"") | O28: =IF($E28="Elec",I28*G28+L28,"") | AW28: =AV28-I28 -> 0
A29: CBE | E29: =IFERROR(VLOOKUP(D29,[1]Données!A:B,2,FALSE),"") | F29: =G29*H29 -> 0 | I29: =SUM(P29:AT29) -> 0 | J29: =IFERROR(I29/H29,"") | L29: =IFERROR((K29*1.25)*G29,"") -> 0 | M29: =IF($E29="Méca",I29*G29+L29,"") | N29: =IF($E29="Calcul",I29*G29+L29,"") | O29: =IF($E29="Elec",I29*G29+L29,"") | AW29: =AV29-I29 -> 0
A30: CBE | E30: =IFERROR(VLOOKUP(D30,[1]Données!A:B,2,FALSE),"") | F30: =G30*H30 -> 0 | I30: =SUM(P30:AT30) -> 0 | J30: =IFERROR(I30/H30,"") | L30: =IFERROR((K30*1.25)*G30,"") -> 0 | M30: =IF($E30="Méca",I30*G30+L30,"") | N30: =IF($E30="Calcul",I30*G30+L30,"") | O30: =IF($E30="Elec",I30*G30+L30,"") | AW30: =AV30-I30 -> 0
A31: CBE | E31: =IFERROR(VLOOKUP(D31,[1]Données!A:B,2,FALSE),"") | F31: =G31*H31 -> 0 | I31: =SUM(P31:AT31) -> 0 | J31: =IFERROR(I31/H31,"") | L31: =IFERROR((K31*1.25)*G31,"") -> 0 | M31: =IF($E31="Méca",I31*G31+L31,"") | N31: =IF($E31="Calcul",I31*G31+L31,"") | O31: =IF($E31="Elec",I31*G31+L31,"") | AW31: =AV31-I31 -> 0
A32: CBE | E32: =IFERROR(VLOOKUP(D32,[1]Données!A:B,2,FALSE),"") | F32: =G32*H32 -> 0 | I32: =SUM(P32:AT32) -> 0 | L32: =IFERROR((K32*1.25)*G32,"") -> 0 | M32: =IF($E32="Méca",I32*G32+L32,"") | N32: =IF($E32="Calcul",I32*G32+L32,"") | O32: =IF($E32="Elec",I32*G32+L32,"") | AW32: =AV32-I32 -> 0
A33: CBE | E33: =IFERROR(VLOOKUP(D33,[1]Données!A:B,2,FALSE),"") | F33: =G33*H33 -> 0 | I33: =SUM(P33:AT33) -> 0 | L33: =IFERROR((K33*1.25)*G33,"") -> 0 | M33: =IF($E33="Méca",I33*G33+L33,"") | N33: =IF($E33="Calcul",I33*G33+L33,"") | O33: =IF($E33="Elec",I33*G33+L33,"") | AW33: =AV33-I33 -> 0
A34: CBE | E34: =IFERROR(VLOOKUP(D34,[1]Données!A:B,2,FALSE),"") | F34: =G34*H34 -> 0 | I34: =SUM(P34:AT34) -> 0 | L34: =IFERROR((K34*1.25)*G34,"") -> 0 | M34: =IF($E34="Méca",I34*G34+L34,"") | N34: =IF($E34="Calcul",I34*G34+L34,"") | O34: =IF($E34="Elec",I34*G34+L34,"") | AW34: =AV34-I34 -> 0
A35: CBE | E35: =IFERROR(VLOOKUP(D35,[1]Données!A:B,2,FALSE),"") | F35: =G35*H35 -> 0 | I35: =SUM(P35:AT35) -> 0 | L35: =IFERROR((K35*1.25)*G35,"") -> 0 | M35: =IF($E35="Méca",I35*G35+L35,"") | N35: =IF($E35="Calcul",I35*G35+L35,"") | O35: =IF($E35="Elec",I35*G35+L35,"") | AW35: =AV35-I35 -> 0
A36: CBE | E36: =IFERROR(VLOOKUP(D36,[1]Données!A:B,2,FALSE),"") | F36: =G36*H36 -> 0 | I36: =SUM(P36:AT36) -> 0 | L36: =IFERROR((K36*1.25)*G36,"") -> 0 | M36: =IF($E36="Méca",I36*G36+L36,"") | N36: =IF($E36="Calcul",I36*G36+L36,"") | O36: =IF($E36="Elec",I36*G36+L36,"") | AW36: =AV36-I36 -> 0
A37: CBE | E37: =IFERROR(VLOOKUP(D37,[1]Données!A:B,2,FALSE),"") | F37: =G37*H37 -> 0 | I37: =SUM(P37:AT37) -> 0 | L37: =IFERROR((K37*1.25)*G37,"") -> 0 | M37: =IF($E37="Méca",I37*G37+L37,"") | N37: =IF($E37="Calcul",I37*G37+L37,"") | O37: =IF($E37="Elec",I37*G37+L37,"") | AW37: =AV37-I37 -> 0
A38: CAS | E38: =IFERROR(VLOOKUP(D38,[1]Données!A:B,2,FALSE),"") | F38: =G38*H38 -> 0 | I38: =SUM(P38:AT38) -> 0 | L38: =IFERROR((K38*1.25)*#REF!,"") | M38: =IF($E38="Méca",I38*G38+L38,"") | N38: =IF($E38="Calcul",I38*G38+L38,"") | O38: =IF($E38="Elec",I38*G38+L38,"")
A39: CAS | E39: =IFERROR(VLOOKUP(D39,[1]Données!A:B,2,FALSE),"") | F39: =G39*H39 -> 0 | I39: =SUM(P39:AT39) -> 0 | L39: =IFERROR((K39*1.25)*#REF!,"") | M39: =IF($E39="Méca",I39*G39+L39,"") | N39: =IF($E39="Calcul",I39*G39+L39,"") | O39: =IF($E39="Elec",I39*G39+L39,"")
A40: CAS | E40: =IFERROR(VLOOKUP(D40,[1]Données!A:B,2,FALSE),"") | F40: =G40*H40 -> 0 | I40: =SUM(P40:AT40) -> 0 | L40: =IFERROR((K40*1.25)*#REF!,"") | M40: =IF($E40="Méca",I40*G40+L40,"") | N40: =IF($E40="Calcul",I40*G40+L40,"") | O40: =IF($E40="Elec",I40*G40+L40,"")
...
